### ▶ 抓住这些异常！

```py
some_list = [1, 2, 3]
try:
    # 这里应该会抛出一个 ``IndexError`` 异常
    print(some_list[4])
except IndexError, ValueError:
    print("Caught!")

try:
    # 这里会抛出一个 ``ValueError`` 异常
    some_list.remove(4)
except IndexError, ValueError:
    print("Caught again!")
```

**Output (Python 2.x):**
```py
Caught!

ValueError: list.remove(x): x not in list
```

**Output (Python 3.x):**
```py
  File "<input>", line 3
    except IndexError, ValueError:
                     ^
SyntaxError: invalid syntax
```

#### 💡 解释

* 如果想在`except`语句中同时捕获多个异常类型，需要把这些类型写成元组(tuple)的形式放在第一个参数的位置。第二个参数是一个可选参数，用来绑定具体捕获异常后的对象。比如，
  ```py
  some_list = [1, 2, 3]
  try:
     # 这里会产生一个 ``ValueError`` 异常
     some_list.remove(4)
  except (IndexError, ValueError), e:
     print("Caught again!")
     print(e)
  ```
  **Output (Python 2.x):**
  ```
  Caught again!
  list.remove(x): x not in list
  ```
  **Output (Python 3.x):**
  ```py
    File "<input>", line 4
      except (IndexError, ValueError), e:
                                       ^
  IndentationError: unindent does not match any outer indentation level
  ```

* 在Python 3中已经弃用了使用逗号分隔异常类型和异常变量了；而是要使用`as`语法了。比如，
  ```py
  some_list = [1, 2, 3]
  try:
      some_list.remove(4)

  except (IndexError, ValueError) as e:
      print("Caught again!")
      print(e)
  ```
  **Output:**
  ```
  Caught again!
  list.remove(x): x not in list
  ```

---